<?xml version="1.0"?>
<robot name="humanoid_10theta_stable">

  <!-- pelvis -->
  <link name="pelvis">
    <inertial>
      <origin xyz="0 0 0" rpy="0 0 0"/>
      <mass value="12.0"/>
      <inertia ixx="0.6" ixy="0.0" ixz="0.0" iyy="0.6" iyz="0.0" izz="0.6"/>
    </inertial>
    <visual>
      <origin xyz="0 0 0.25" rpy="0 0 0"/>
      <geometry><box size="0.25 0.15 0.18"/></geometry>
    </visual>
    <collision>
      <origin xyz="0 0 0.25" rpy="0 0 0"/>
      <geometry><box size="0.25 0.15 0.18"/></geometry>
    </collision>
  </link>

  <!-- RIGHT LEG -->
  <link name="right_thigh">
    <inertial>
      <origin xyz="0 -0.05 -0.18"/>
      <mass value="4.0"/>
      <inertia ixx="0.04" ixy="0" ixz="0" iyy="0.04" iyz="0" izz="0.015"/>
    </inertial>
    <visual><origin xyz="0 -0.05 -0.18"/><geometry><cylinder length="0.36" radius="0.06"/></geometry></visual>
    <collision><origin xyz="0 -0.05 -0.18"/><geometry><cylinder length="0.36" radius="0.06"/></geometry></collision>
  </link>
  <joint name="right_hip_pitch" type="revolute">
    <parent link="pelvis"/>
    <child link="right_thigh"/>
    <origin xyz="0 -0.08 -0.05"/>
    <axis xyz="0 1 0"/>
    <limit lower="-2.3" upper="2.3" effort="200" velocity="5.0"/>
  </joint>

  <link name="right_shank">
    <inertial>
      <origin xyz="0 -0.02 -0.17"/>
      <mass value="3.0"/>
      <inertia ixx="0.025" ixy="0" ixz="0" iyy="0.025" iyz="0" izz="0.012"/>
    </inertial>
    <visual><origin xyz="0 -0.02 -0.17"/><geometry><cylinder length="0.34" radius="0.05"/></geometry></visual>
    <collision><origin xyz="0 -0.02 -0.17"/><geometry><cylinder length="0.34" radius="0.05"/></geometry></collision>
  </link>
  <joint name="right_knee" type="revolute">
    <parent link="right_thigh"/>
    <child link="right_shank"/>
    <origin xyz="0 0 -0.36"/>
    <axis xyz="0 1 0"/>
    <limit lower="-1.5" upper="2.0" effort="150" velocity="5.0"/>
  </joint>

  <link name="right_foot">
    <inertial>
      <origin xyz="0 0 -0.05"/>
      <mass value="1.0"/>
      <inertia ixx="0.002" ixy="0" ixz="0" iyy="0.002" iyz="0" izz="0.002"/>
    </inertial>
    <visual><origin xyz="0 0 -0.05"/><geometry><box size="0.22 0.08 0.03"/></geometry></visual>
    <collision><origin xyz="0 0 -0.05"/><geometry><box size="0.22 0.08 0.03"/></geometry></collision>
  </link>
  <joint name="right_ankle" type="revolute">
    <parent link="right_shank"/>
    <child link="right_foot"/>
    <origin xyz="0 0 -0.34"/>
    <axis xyz="0 1 0"/>
    <limit lower="-1.57" upper="1.8" effort="80" velocity="8.0"/>
  </joint>

  <!-- LEFT LEG -->
  <link name="left_thigh">
    <inertial>
      <origin xyz="0 0.05 -0.18"/>
      <mass value="4.0"/>
      <inertia ixx="0.04" ixy="0" ixz="0" iyy="0.04" iyz="0" izz="0.015"/>
    </inertial>
    <visual><origin xyz="0 0.05 -0.18"/><geometry><cylinder length="0.36" radius="0.06"/></geometry></visual>
    <collision><origin xyz="0 0.05 -0.18"/><geometry><cylinder length="0.36" radius="0.06"/></geometry></collision>
  </link>
  <joint name="left_hip_pitch" type="revolute">
    <parent link="pelvis"/>
    <child link="left_thigh"/>
    <origin xyz="0 0.08 -0.05"/>
    <axis xyz="0 1 0"/>
    <limit lower="-2.3" upper="2.3" effort="200" velocity="5.0"/>
  </joint>

  <link name="left_shank">
    <inertial>
      <origin xyz="0 0.02 -0.17"/>
      <mass value="3.0"/>
      <inertia ixx="0.025" ixy="0" ixz="0" iyy="0.025" iyz="0" izz="0.012"/>
    </inertial>
    <visual><origin xyz="0 0.02 -0.17"/><geometry><cylinder length="0.34" radius="0.05"/></geometry></visual>
    <collision><origin xyz="0 0.02 -0.17"/><geometry><cylinder length="0.34" radius="0.05"/></geometry></collision>
  </link>
  <joint name="left_knee" type="revolute">
    <parent link="left_thigh"/>
    <child link="left_shank"/>
    <origin xyz="0 0 -0.36"/>
    <axis xyz="0 1 0"/>
    <limit lower="-1.5" upper="2.0" effort="150" velocity="5.0"/>
  </joint>

  <link name="left_foot">
    <inertial>
      <origin xyz="0 0 -0.05"/>
      <mass value="1.0"/>
      <inertia ixx="0.002" ixy="0" ixz="0" iyy="0.002" iyz="0" izz="0.002"/>
    </inertial>
    <visual><origin xyz="0 0 -0.05"/><geometry><box size="0.22 0.08 0.03"/></geometry></visual>
    <collision><origin xyz="0 0 -0.05"/><geometry><box size="0.22 0.08 0.03"/></geometry></collision>
  </link>
  <joint name="left_ankle" type="revolute">
    <parent link="left_shank"/>
    <child link="left_foot"/>
    <origin xyz="0 0 -0.34"/>
    <axis xyz="0 1 0"/>
    <limit lower="-1.57" upper="1.8" effort="80" velocity="8.0"/>
  </joint>

  <!-- torso -->
  <link name="torso">
    <inertial>
      <origin xyz="0 0 0.12"/>
      <mass value="10.0"/>
      <inertia ixx="0.25" ixy="0" ixz="0" iyy="0.25" iyz="0" izz="0.25"/>
    </inertial>
    <visual><origin xyz="0 0 0.12"/><geometry><box size="0.28 0.18 0.24"/></geometry></visual>
    <collision><origin xyz="0 0 0.12"/><geometry><box size="0.28 0.18 0.24"/></geometry></collision>
  </link>
  <joint name="pelvis_to_torso" type="fixed">
    <parent link="pelvis"/>
    <child link="torso"/>
    <origin xyz="0 0 0.10"/>
  </joint>

  <!-- RIGHT ARM -->
  <link name="right_upperarm">
    <inertial>
      <origin xyz="0 -0.06 0.0"/> <mass value="2.0"/>
      <inertia ixx="0.025" ixy="0" ixz="0" iyy="0.025" iyz="0" izz="0.015"/>
    </inertial>
    <visual><origin xyz="0 -0.06 0.0"/><geometry><cylinder length="0.26" radius="0.04"/></geometry></visual>
    <collision><origin xyz="0 -0.06 0.0"/><geometry><cylinder length="0.26" radius="0.04"/></geometry></collision>
  </link>
  <joint name="right_shoulder_pitch" type="revolute">
    <parent link="torso"/>
    <child link="right_upperarm"/>
    <origin xyz="0 -0.14 0.08"/>
    <axis xyz="0 1 0"/>
    <limit lower="-1.5" upper="1.5" effort="80" velocity="5.0"/>
  </joint>

  <link name="right_forearm">
    <inertial><origin xyz="0 -0.02 -0.12"/><mass value="1.5"/>
      <inertia ixx="0.015" ixy="0" ixz="0" iyy="0.015" iyz="0" izz="0.007"/>
    </inertial>
    <visual><origin xyz="0 -0.02 -0.12"/><geometry><cylinder length="0.24" radius="0.035"/></geometry></visual>
    <collision><origin xyz="0 -0.02 -0.12"/><geometry><cylinder length="0.24" radius="0.035"/></geometry></collision>
  </link>
  <joint name="right_elbow" type="revolute">
    <parent link="right_upperarm"/>
    <child link="right_forearm"/>
    <origin xyz="0 0 -0.26"/>
    <axis xyz="0 1 0"/>
    <limit lower="-2.5" upper="3" effort="50" velocity="6.0"/>
  </joint>

  <link name="right_hand">
    <inertial><origin xyz="0 0 0"/><mass value="0.5"/>
      <inertia ixx="0.001" ixy="0" ixz="0" iyy="0.001" iyz="0" izz="0.001"/>
    </inertial>
    <visual><origin xyz="0 0 0"/><geometry><box size="0.06 0.02 0.1"/></geometry></visual>
    <collision><origin xyz="0 0 0"/><geometry><box size="0.06 0.02 0.1"/></geometry></collision>
  </link>
  <joint name="right_wrist" type="revolute">
    <parent link="right_forearm"/>
    <child link="right_hand"/>
    <axis xyz="0 1 0"/>
    <limit lower="-1.57" upper="1.57" effort="10" velocity="5"/>
  </joint>

  <!-- LEFT ARM -->
  <link name="left_upperarm">
    <inertial><origin xyz="0 0.06 0.0"/><mass value="2.0"/>
      <inertia ixx="0.025" ixy="0" ixz="0" iyy="0.025" iyz="0" izz="0.015"/>
    </inertial>
    <visual><origin xyz="0 0.06 0.0"/><geometry><cylinder length="0.26" radius="0.04"/></geometry></visual>
    <collision><origin xyz="0 0.06 0.0"/><geometry><cylinder length="0.26" radius="0.04"/></geometry></collision>
  </link>
  <joint name="left_shoulder_pitch" type="revolute">
    <parent link="torso"/>
    <child link="left_upperarm"/>
    <origin xyz="0 0.14 0.08"/>
    <axis xyz="0 1 0"/>
    <limit lower="-2.5" upper="3" effort="80" velocity="5.0"/>
  </joint>

  <link name="left_forearm">
    <inertial><origin xyz="0 0.02 -0.12"/><mass value="1.5"/>
      <inertia ixx="0.015" ixy="0" ixz="0" iyy="0.015" iyz="0" izz="0.007"/>
    </inertial>
    <visual><origin xyz="0 0.02 -0.12"/><geometry><cylinder length="0.24" radius="0.035"/></geometry></visual>
    <collision><origin xyz="0 0.02 -0.12"/><geometry><cylinder length="0.24" radius="0.035"/></geometry></collision>
  </link>
  <joint name="left_elbow" type="revolute">
    <parent link="left_upperarm"/>
    <child link="left_forearm"/>
    <origin xyz="0 0 -0.26"/>
    <axis xyz="0 1 0"/>
    <limit lower="-2.5" upper="3" effort="50" velocity="6.0"/>
  </joint>

  <link name="left_hand">
    <inertial><origin xyz="0 0 0"/><mass value="0.5"/>
      <inertia ixx="0.001" ixy="0" ixz="0" iyy="0.001" iyz="0" izz="0.001"/>
    </inertial>
    <visual><origin xyz="0 0 0"/><geometry><box size="0.06 0.02 0.1"/></geometry></visual>
    <collision><origin xyz="0 0 0"/><geometry><box size="0.06 0.02 0.1"/></geometry></collision>
  </link>
  <joint name="left_wrist" type="revolute">
    <parent link="left_forearm"/>
    <child link="left_hand"/>
    <axis xyz="0 1 0"/>
    <limit lower="-1.57" upper="1.57" effort="10" velocity="5"/>
  </joint>

  <!-- head -->
  <link name="head">
    <inertial><origin xyz="0 0 0.09"/><mass value="1.5"/><inertia ixx="0.015" ixy="0" ixz="0" iyy="0.015" iyz="0" izz="0.015"/></inertial>
    <visual><origin xyz="0 0 0.09"/><geometry><sphere radius="0.08"/></geometry></visual>
    <collision><origin xyz="0 0 0.09"/><geometry><sphere radius="0.08"/></geometry></collision>
  </link>
  <joint name="neck" type="fixed">
    <parent link="torso"/>
    <child link="head"/>
    <origin xyz="0 0 0.27"/>
  </joint>

</robot>
